Workbook

Sheet README
A1: ARPOL Laser-Cutting Insourcing — 5-Year TCO Model
A3: Purpose
A4: Evaluate whether ARPOL should insource laser-cutting (currently subcontracted), and if so, with which supplier (EU vs China).
A5: Compares three scenarios over 5 years: Continue Outsourcing | EU Insource | China Insource.
A7: How to use
A8: 1. Fill in the Assumptions tab — all yellow cells. Replace placeholder values with researched inputs from Team B.
A9: 2. Every assumption cell links to a Source column. Populate the Source column for every input used.
A10: 3. The three Scenario tabs (Current State, EU Insource, China Insource) pull from Assumptions automatically.
A11: 4. The TCO Comparison tab consolidates the three scenarios and computes payback.
A12: 5. Sensitivity tab tests how payback changes under different volume and CAPEX assumptions.
A13: 6. Executive Summary tab is the slide-ready output for the presentation.
A15: Colour conventions (industry standard)
A16: Blue text | B16: Hardcoded input (you can change)
A17: Black text | B17: Formula or calculation (do not edit)
A18: Green text | B18: Link from another sheet
A19: Yellow fill | B19: Key assumption — needs to be sourced/validated
A22: Sheet map
A23: Assumptions | B23: All inputs in one place. Every model number traces back here.
A24: Current State | B24: Baseline scenario: continue outsourcing laser-cutting. Annual cost + 5-yr NPV.
A25: EU Insource | B25: Insource scenario with EU supplier (Trumpf/Bystronic archetype).
A26: China Insource | B26: Insource scenario with Chinese supplier (Bodor/HSG archetype).
A27: TCO Comparison | B27: 5-year side-by-side. Cumulative cash position. Payback period.
A28: Working Capital | B28: SKU rationalisation impact: coil-to-sheet inventory release.
A29: Sensitivity | B29: Volume cases (low/base/high) × CAPEX cases (low/base/high).
A30: Executive Summary | B30: One-page output for the presentation.

Sheet Assumptions
A1: Assumption Register — all model inputs
A3: # | B3: Input | C3: Value | D3: Unit | E3: Source | F3: Notes
A4: CURRENT STATE BASELINE (Continue Outsourcing)
B5: Annual subcontract spend on laser-cutting | C5: 120000 | D5: €/year | E5: Client (Manuel via Prof. Felipe) | F5: PLACEHOLDER — replace once client data arrives
B6: Annual production volume (current) | C6: 50000 | D6: units | E6: Client | F6: PLACEHOLDER
B7: Press-cutting annual operational cost | C7: 80000 | D7: €/year | E7: Client / INE benchmark | F7: Labour + energy + maintenance on 25-yr-old press
B8: Current scrap & rework cost | C8: 15000 | D8: €/year | E8: Client / industry benchmark | F8: Estimate as % of revenue if no client data
A9: VOLUME GROWTH (tied to €4M → €8M by 2028)
B10: Annual volume growth rate | C10: 0.15 | D10: %/year | E10: Derived from €4M→€8M plan | F10: 15% compound matches doubling by 2028
A11: EU SUPPLIER SCENARIO (Trumpf/Bystronic archetype)
B12: EU laser cutter equipment cost | C12: 300000 | D12: € | E12: Trumpf / Bystronic published pricing, Statista | F12: 3–6kW fiber, validate range
B13: Installation & commissioning (EU) | C13: 0.12 | D13: % of CAPEX | E13: Supplier whitepapers | F13: Typical 8–15%
B14: Operator training cost (EU) | C14: 10000 | D14: € one-off | E14: Supplier whitepapers | F14: Per operator
B15: Ancillary equipment (extraction, chiller) | C15: 25000 | D15: € | E15: Industry benchmark
B16: EU annual maintenance contract | C16: 0.06 | D16: % of CAPEX/year | E16: Supplier whitepapers | F16: Typical 5–8%
B17: EU delivery lead time | C17: 16 | D17: weeks | E17: Supplier published lead times
A18: CHINA SUPPLIER SCENARIO (Bodor/HSG archetype)
B19: China laser cutter equipment cost | C19: 110000 | D19: € | E19: Bodor / HSG / Han's Laser pricing | F19: 3–6kW fiber equivalent
B20: Installation & commissioning (China) | C20: 0.2 | D20: % of CAPEX | E20: Trade publications | F20: Higher due to remote support
B21: Operator training cost (China) | C21: 8000 | D21: € one-off | E21: Supplier estimates
B22: Shipping & customs (China → Spain) | C22: 12000 | D22: € one-off | E22: Freight forwarder benchmarks
B23: Ancillary equipment (extraction, chiller) | C23: 25000 | D23: € | E23: Industry benchmark | F23: Same as EU case
B24: China annual maintenance / parts | C24: 0.04 | D24: % of CAPEX/year | E24: Industry estimates | F24: Often pay-per-incident; flag risk
B25: China delivery lead time | C25: 24 | D25: weeks | E25: Supplier published lead times
A26: OPERATING COSTS (both insource scenarios)
B27: Annual operating hours | C27: 1800 | D27: hours/year | E27: Client / 1-shift assumption | F27: ~225 working days × 8h
B28: Laser power consumption under load | C28: 20 | D28: kW | E28: Supplier specs | F28: Includes auxiliary (chiller, extraction)
B29: Spanish industrial electricity rate | C29: 0.18 | D29: €/kWh | E29: Eurostat / INE | F29: Verify current rate
B30: Consumables cost per operating hour | C30: 5 | D30: €/hour | E30: Trade publications | F30: Nozzles, lenses, assist gas
B31: Operator wage (loaded) | C31: 35000 | D31: €/year per operator | E31: INE Spanish manufacturing wages | F31: Includes social charges
B32: Operators required | C32: 1 | D32: FTE | E32: Standard 1-shift operation
B33: Equipment useful life | C33: 8 | D33: years | E33: Spanish accounting standards | F33: Used for depreciation horizon
A34: WORKING CAPITAL (SKU rationalisation insight)
B35: Current coil SKU count (rings per thickness) | C35: 8 | D35: SKUs/thickness | E35: Manuel interview | F35: CONFIRMED
B36: Number of thickness grades | C36: 5 | D36: thicknesses | E36: Client estimate
B37: Avg inventory value per coil SKU | C37: 4000 | D37: € | E37: Client / steel pricing benchmark
B38: Inventory holding cost rate | C38: 0.2 | D38: % of inv value/year | E38: Industry benchmark | F38: Typical 15-25% for industrial SMEs
B39: SKU reduction with coil-to-sheet shift | C39: 0.7 | D39: % reduction | E39: Hypothesis from Manuel interview | F39: Coils unified by thickness; sheets serve more SKUs
A40: FINANCIAL PARAMETERS
B41: Discount rate (WACC proxy) | C41: 0.08 | D41: % | E41: Spanish SME benchmark | F41: For NPV calculations
...

Sheet Current State
A1: Current State — Continue Outsourcing Laser-Cutting
A3: Baseline scenario: ARPOL continues subcontracting laser-cutting and operates the existing 25-yr-old press.
A5: Line item | B5: Year 0 | C5: Year 1 | D5: Year 2 | E5: Year 3 | F5: Year 4 | G5: Year 5
A6: Subcontract spend | B6: 0 | C6: =-Assumptions!$C$5*(1+Assumptions!$C$10)^0 -> -120000 | D6: =-Assumptions!$C$5*(1+Assumptions!$C$10)^1 -> -138000 | E6: =-Assumptions!$C$5*(1+Assumptions!$C$10)^2 -> -158700 | F6: =-Assumptions!$C$5*(1+Assumptions!$C$10)^3 -> -182505 | G6: =-Assumptions!$C$5*(1+Assumptions!$C$10)^4 -> -209880.75
A7: Press operational cost | B7: 0 | C7: =-Assumptions!$C$7*(1+Assumptions!$C$42)^0 -> -80000 | D7: =-Assumptions!$C$7*(1+Assumptions!$C$42)^1 -> -82000 | E7: =-Assumptions!$C$7*(1+Assumptions!$C$42)^2 -> -84050 | F7: =-Assumptions!$C$7*(1+Assumptions!$C$42)^3 -> -86151.25 | G7: =-Assumptions!$C$7*(1+Assumptions!$C$42)^4 -> -88305.031
A8: Scrap & rework cost | B8: 0 | C8: =-Assumptions!$C$8*(1+Assumptions!$C$42)^0 -> -15000 | D8: =-Assumptions!$C$8*(1+Assumptions!$C$42)^1 -> -15375 | E8: =-Assumptions!$C$8*(1+Assumptions!$C$42)^2 -> -15759.375 | F8: =-Assumptions!$C$8*(1+Assumptions!$C$42)^3 -> -16153.359 | G8: =-Assumptions!$C$8*(1+Assumptions!$C$42)^4 -> -16557.193
A9: Total annual cash flow | B9: =SUM(B6:B8) -> 0 | C9: =SUM(C6:C8) -> -215000 | D9: =SUM(D6:D8) -> -235375 | E9: =SUM(E6:E8) -> -258509.37 | F9: =SUM(F6:F8) -> -284809.61 | G9: =SUM(G6:G8) -> -314742.97
A10: Cumulative cash flow | B10: =B9 -> 0 | C10: =B10+C9 -> -215000 | D10: =C10+D9 -> -450375 | E10: =D10+E9 -> -708884.38 | F10: =E10+F9 -> -993693.98 | G10: =F10+G9 -> -1308437
A12: 5-year cumulative cost of continuing to outsource | B12: =G10 -> -1308437

Sheet EU Insource
A1: EU Insource Scenario — Trumpf/Bystronic archetype
A5: Line item | B5: Year 0 | C5: Year 1 | D5: Year 2 | E5: Year 3 | F5: Year 4 | G5: Year 5
A6: — CAPEX (Year 0) —
A7: Equipment cost | B7: =-Assumptions!$C$12 -> -300000
A8: Installation & commissioning | B8: =-Assumptions!$C$12*Assumptions!$C$13 -> -36000
A9: Operator training | B9: =-Assumptions!$C$14*Assumptions!$C$32 -> -10000
A10: Ancillary equipment | B10: =-Assumptions!$C$15 -> -25000
A11: Total CAPEX (Year 0) | B11: =SUM(B7:B10) -> -371000
A13: — Annual operating costs (Years 1–5) —
A14: Energy | C14: =-Assumptions!$C$27*Assumptions!$C$28*Assumptions!$C$29*(1+Assumptions!$C$42)^0 -> -6480 | D14: =-Assumptions!$C$27*Assumptions!$C$28*Assumptions!$C$29*(1+Assumptions!$C$42)^1 -> -6642 | E14: =-Assumptions!$C$27*Assumptions!$C$28*Assumptions!$C$29*(1+Assumptions!$C$42)^2 -> -6808.05 | F14: =-Assumptions!$C$27*Assumptions!$C$28*Assumptions!$C$29*(1+Assumptions!$C$42)^3 -> -6978.2512 | G14: =-Assumptions!$C$27*Assumptions!$C$28*Assumptions!$C$29*(1+Assumptions!$C$42)^4 -> -7152.7075
A15: Consumables (nozzles, lenses, gas) | C15: =-Assumptions!$C$27*Assumptions!$C$30*(1+Assumptions!$C$42)^0 -> -9000 | D15: =-Assumptions!$C$27*Assumptions!$C$30*(1+Assumptions!$C$42)^1 -> -9225 | E15: =-Assumptions!$C$27*Assumptions!$C$30*(1+Assumptions!$C$42)^2 -> -9455.625 | F15: =-Assumptions!$C$27*Assumptions!$C$30*(1+Assumptions!$C$42)^3 -> -9692.0156 | G15: =-Assumptions!$C$27*Assumptions!$C$30*(1+Assumptions!$C$42)^4 -> -9934.316
A16: Maintenance contract | C16: =-Assumptions!$C$12*Assumptions!$C$16*(1+Assumptions!$C$42)^0 -> -18000 | D16: =-Assumptions!$C$12*Assumptions!$C$16*(1+Assumptions!$C$42)^1 -> -18450 | E16: =-Assumptions!$C$12*Assumptions!$C$16*(1+Assumptions!$C$42)^2 -> -18911.25 | F16: =-Assumptions!$C$12*Assumptions!$C$16*(1+Assumptions!$C$42)^3 -> -19384.031 | G16: =-Assumptions!$C$12*Assumptions!$C$16*(1+Assumptions!$C$42)^4 -> -19868.632
A17: Operator labour | C17: =-Assumptions!$C$31*Assumptions!$C$32*(1+Assumptions!$C$42)^0 -> -35000 | D17: =-Assumptions!$C$31*Assumptions!$C$32*(1+Assumptions!$C$42)^1 -> -35875 | E17: =-Assumptions!$C$31*Assumptions!$C$32*(1+Assumptions!$C$42)^2 -> -36771.875 | F17: =-Assumptions!$C$31*Assumptions!$C$32*(1+Assumptions!$C$42)^3 -> -37691.172 | G17: =-Assumptions!$C$31*Assumptions!$C$32*(1+Assumptions!$C$42)^4 -> -38633.451
A18: Total annual operating cost | C18: =SUM(C14:C17) -> -68480 | D18: =SUM(D14:D17) -> -70192 | E18: =SUM(E14:E17) -> -71946.8 | F18: =SUM(F14:F17) -> -73745.47 | G18: =SUM(G14:G17) -> -75589.107
A20: TOTAL annual cash flow | B20: =B11 -> -371000 | C20: =C18 -> -68480 | D20: =D18 -> -70192 | E20: =E18 -> -71946.8 | F20: =F18 -> -73745.47 | G20: =G18 -> -75589.107
A21: Cumulative cash flow | B21: =B20 -> -371000 | C21: =B21+C20 -> -439480 | D21: =C21+D20 -> -509672 | E21: =D21+E20 -> -581618.8 | F21: =E21+F20 -> -655364.27 | G21: =F21+G20 -> -730953.38

Sheet China Insource
A1: China Insource Scenario — Bodor/HSG archetype
A5: Line item | B5: Year 0 | C5: Year 1 | D5: Year 2 | E5: Year 3 | F5: Year 4 | G5: Year 5
A6: — CAPEX (Year 0) —
A7: Equipment cost | B7: =-Assumptions!$C$19 -> -110000
A8: Installation & commissioning | B8: =-Assumptions!$C$19*Assumptions!$C$20 -> -22000
A9: Operator training | B9: =-Assumptions!$C$21*Assumptions!$C$32 -> -8000
A10: Ancillary equipment | B10: =-Assumptions!$C$23 -> -25000
A11: Shipping & customs | B11: =-Assumptions!$C$22 -> -12000
A12: Total CAPEX (Year 0) | B12: =SUM(B7:B11) -> -177000
A14: — Annual operating costs (Years 1–5) —
A15: Energy | C15: =-Assumptions!$C$27*Assumptions!$C$28*Assumptions!$C$29*(1+Assumptions!$C$42)^0 -> -6480 | D15: =-Assumptions!$C$27*Assumptions!$C$28*Assumptions!$C$29*(1+Assumptions!$C$42)^1 -> -6642 | E15: =-Assumptions!$C$27*Assumptions!$C$28*Assumptions!$C$29*(1+Assumptions!$C$42)^2 -> -6808.05 | F15: =-Assumptions!$C$27*Assumptions!$C$28*Assumptions!$C$29*(1+Assumptions!$C$42)^3 -> -6978.2512 | G15: =-Assumptions!$C$27*Assumptions!$C$28*Assumptions!$C$29*(1+Assumptions!$C$42)^4 -> -7152.7075
A16: Consumables (nozzles, lenses, gas) | C16: =-Assumptions!$C$27*Assumptions!$C$30*(1+Assumptions!$C$42)^0 -> -9000 | D16: =-Assumptions!$C$27*Assumptions!$C$30*(1+Assumptions!$C$42)^1 -> -9225 | E16: =-Assumptions!$C$27*Assumptions!$C$30*(1+Assumptions!$C$42)^2 -> -9455.625 | F16: =-Assumptions!$C$27*Assumptions!$C$30*(1+Assumptions!$C$42)^3 -> -9692.0156 | G16: =-Assumptions!$C$27*Assumptions!$C$30*(1+Assumptions!$C$42)^4 -> -9934.316
A17: Maintenance contract | C17: =-Assumptions!$C$19*Assumptions!$C$24*(1+Assumptions!$C$42)^0 -> -4400 | D17: =-Assumptions!$C$19*Assumptions!$C$24*(1+Assumptions!$C$42)^1 -> -4510 | E17: =-Assumptions!$C$19*Assumptions!$C$24*(1+Assumptions!$C$42)^2 -> -4622.75 | F17: =-Assumptions!$C$19*Assumptions!$C$24*(1+Assumptions!$C$42)^3 -> -4738.3187 | G17: =-Assumptions!$C$19*Assumptions!$C$24*(1+Assumptions!$C$42)^4 -> -4856.7767
A18: Operator labour | C18: =-Assumptions!$C$31*Assumptions!$C$32*(1+Assumptions!$C$42)^0 -> -35000 | D18: =-Assumptions!$C$31*Assumptions!$C$32*(1+Assumptions!$C$42)^1 -> -35875 | E18: =-Assumptions!$C$31*Assumptions!$C$32*(1+Assumptions!$C$42)^2 -> -36771.875 | F18: =-Assumptions!$C$31*Assumptions!$C$32*(1+Assumptions!$C$42)^3 -> -37691.172 | G18: =-Assumptions!$C$31*Assumptions!$C$32*(1+Assumptions!$C$42)^4 -> -38633.451
A19: Total annual operating cost | C19: =SUM(C15:C18) -> -54880 | D19: =SUM(D15:D18) -> -56252 | E19: =SUM(E15:E18) -> -57658.3 | F19: =SUM(F15:F18) -> -59099.757 | G19: =SUM(G15:G18) -> -60577.251
A21: TOTAL annual cash flow | B21: =B12 -> -177000 | C21: =C19 -> -54880 | D21: =D19 -> -56252 | E21: =E19 -> -57658.3 | F21: =F19 -> -59099.757 | G21: =G19 -> -60577.251
A22: Cumulative cash flow | B22: =B21 -> -177000 | C22: =B22+C21 -> -231880 | D22: =C22+D21 -> -288132 | E22: =D22+E21 -> -345790.3 | F22: =E22+F21 -> -404890.06 | G22: =F22+G21 -> -465467.31

Sheet TCO Comparison
A1: 5-Year TCO Comparison & Payback Analysis
A3: Compares the three scenarios side-by-side. Payback measured against the Continue Outsourcing baseline.
A5: Scenario | B5: Year 0 | C5: Year 1 | D5: Year 2 | E5: Year 3 | F5: Year 4 | G5: Year 5 | H5: 5-yr Total
A6: Continue Outsourcing — annual | B6: ='Current State'!B9 -> 0 | C6: ='Current State'!C9 -> -215000 | D6: ='Current State'!D9 -> -235375 | E6: ='Current State'!E9 -> -258509.37 | F6: ='Current State'!F9 -> -284809.61 | G6: ='Current State'!G9 -> -314742.97 | H6: =SUM(B6:G6) -> -1308437
A7: EU Insource — annual | B7: ='EU Insource'!B20 -> -371000 | C7: ='EU Insource'!C20 -> -68480 | D7: ='EU Insource'!D20 -> -70192 | E7: ='EU Insource'!E20 -> -71946.8 | F7: ='EU Insource'!F20 -> -73745.47 | G7: ='EU Insource'!G20 -> -75589.107 | H7: =SUM(B7:G7) -> -730953.38
A8: China Insource — annual | B8: ='China Insource'!B21 -> -177000 | C8: ='China Insource'!C21 -> -54880 | D8: ='China Insource'!D21 -> -56252 | E8: ='China Insource'!E21 -> -57658.3 | F8: ='China Insource'!F21 -> -59099.757 | G8: ='China Insource'!G21 -> -60577.251 | H8: =SUM(B8:G8) -> -465467.31
A10: — Cumulative cash position —
A11: Continue Outsourcing — cumulative | B11: ='Current State'!B10 -> 0 | C11: ='Current State'!C10 -> -215000 | D11: ='Current State'!D10 -> -450375 | E11: ='Current State'!E10 -> -708884.38 | F11: ='Current State'!F10 -> -993693.98 | G11: ='Current State'!G10 -> -1308437
A12: EU Insource — cumulative | B12: ='EU Insource'!B21 -> -371000 | C12: ='EU Insource'!C21 -> -439480 | D12: ='EU Insource'!D21 -> -509672 | E12: ='EU Insource'!E21 -> -581618.8 | F12: ='EU Insource'!F21 -> -655364.27 | G12: ='EU Insource'!G21 -> -730953.38
A13: China Insource — cumulative | B13: ='China Insource'!B22 -> -177000 | C13: ='China Insource'!C22 -> -231880 | D13: ='China Insource'!D22 -> -288132 | E13: ='China Insource'!E22 -> -345790.3 | F13: ='China Insource'!F22 -> -404890.06 | G13: ='China Insource'!G22 -> -465467.31
A15: — Cumulative savings vs Continue Outsourcing —
A16: EU Insource — savings (vs outsource) | B16: =B12-B11 -> -371000 | C16: =C12-C11 -> -224480 | D16: =D12-D11 -> -59297 | E16: =E12-E11 -> 127265.57 | F16: =F12-F11 -> 338329.71 | G16: =G12-G11 -> 577483.58
A17: China Insource — savings (vs outsource) | B17: =B13-B11 -> -177000 | C17: =C13-C11 -> -16880 | D17: =D13-D11 -> 162243 | E17: =E13-E11 -> 363094.08 | F17: =F13-F11 -> 588803.93 | G17: =G13-G11 -> 842969.65
A20: — Payback period (years to break even vs outsourcing) —
A21: EU Insource — payback year | B21: =IFERROR(MATCH(TRUE(),INDEX(B16:G16>=0,0),0)-1,"> 5 yrs") -> 3
A22: China Insource — payback year | B22: =IFERROR(MATCH(TRUE(),INDEX(B17:G17>=0,0),0)-1,"> 5 yrs") -> 2

Sheet Working Capital
A1: Working Capital Release — SKU Rationalisation Impact
A3: Coil-to-sheet shift consolidates ~8 rings per thickness into unified sheet inventory. This is the differentiating insight from the Manuel interview.
A5: Calculation | B5: Value | C5: Source / Formula
A6: Coil SKUs per thickness | B6: =Assumptions!$C$35 -> 8 | C6: Assumption #26 (confirmed by Manuel)
A7: × Number of thickness grades | B7: =Assumptions!$C$36 -> 5 | C7: Assumption #27
A8: → Total coil SKUs held today | B8: =B6*B7 -> 40
A9: × Avg inventory value per SKU | B9: =Assumptions!$C$37 -> 4000 | C9: Assumption #28
A10: → Current coil inventory value | B10: =B8*B9 -> 160000
A12: SKU reduction rate (sheets unify by thickness) | B12: =Assumptions!$C$39 -> 0.7 | C12: Assumption #30 (hypothesis, validate)
A13: Inventory release (€ one-time) | B13: =B10*B12 -> 112000
A15: × Inventory holding cost rate | B15: =Assumptions!$C$38 -> 0.2
A16: → Inventory release (€ one-time) | B16: =B13*B15 -> 22400
A18: 5-year total WC benefit | B18: =B13+B17*5 -> 112000 | C18: One-time release + 5 yrs of holding cost saved
A19: → Annual holding cost saving (€/year)

Sheet Sensitivity
A1: Sensitivity Analysis — Payback under different scenarios
A3: Tests how robust the recommendation is to volume and CAPEX variation. Manual inputs — duplicate the model with different assumption values to populate.
A5: Scenario name | B5: Volume case | C5: CAPEX case | D5: EU payback (yrs) | E5: China payback (yrs) | F5: Comment
A6: Base case | B6: Base (15% growth) | C6: Mid-range | F6: Replace EU/China cells with manual values from rerun
A7: Low volume | B7: Conservative (8% growth) | C7: Mid-range | F7: Tests if growth slower than €4M→€8M plan
A8: High volume | B8: Optimistic (20% growth) | C8: Mid-range | F8: Tests upside case
A9: Low CAPEX | B9: Base | C9: EU at low end / China at low end
A10: High CAPEX | B10: Base | C10: EU at high end / China at high end
A11: Subcontract -20% | B11: Base | C11: Mid-range | F11: Tests if outsourcing is cheaper than estimated
A12: Subcontract +20% | B12: Base | C12: Mid-range | F12: Tests if outsourcing is more expensive

Sheet Executive Summary
A1: Executive Summary — Slide-Ready Output
A3: This sheet pulls headline numbers from the model. Use directly in the presentation.
A5: Headline metric | B5: Continue Outsourcing | C5: EU Insource | D5: China Insource
A6: Year 0 CAPEX | B6: 0 | C6: ='EU Insource'!B11 -> -371000 | D6: ='China Insource'!B12 -> -177000
A7: 5-year cumulative cash flow | B7: ='Current State'!G10 -> -1308437 | C7: ='EU Insource'!G21 -> -730953.38 | D7: ='China Insource'!G22 -> -465467.31
A8: 5-yr savings vs outsourcing | B8: — | C8: ='TCO Comparison'!G16 -> 577483.58 | D8: ='TCO Comparison'!G17 -> 842969.65
A9: Payback period | B9: n/a | C9: ='TCO Comparison'!B21 -> 3 | D9: ='TCO Comparison'!B22 -> 2
A11: Working capital release (one-time) | B11: ='Working Capital'!B13 -> 112000 | C11: Applies to both insource scenarios
A14: KEY MESSAGES FOR THE BOARD
A15: 1. Insourcing is structurally favoured over continuing the subcontract.
A16: 2. The SKU rationalisation (coil-to-sheet) releases working capital independently of supplier choice.
A17: 3. Supplier trade-off: EU = lower risk, longer payback. China = faster payback, higher operational risk.
A18: 4. Payback sits within ARPOL's expected hurdle (validate with Finance).
A19: 5. Pending data: subcontract baseline, current press unit economics. Numbers above use placeholders.
